Function `sample_debug` raised an exception:
Traceback (most recent call last):
  File "c:\dev\llm_debug\adornment\adornment\adornment.py", line 24, in wrapper
    return func(*args, **kwargs)
           ^^^^^^^^^^^^^^^^^^^^^
  File "c:\dev\llm_debug\adornment\test.py", line 8, in sample_debug
    return 10 / x  # This will raise a ZeroDivisionError when x is 0
           ~~~^~~
ZeroDivisionError: division by zero

LLM Reflection 1:
It looks like the decorated `sample_debug` function is raising a `ZeroDivisionError` because it attempts to divide 10 by the parameter `x`, which was 0 in this case. To handle this error, you can add a check within the function to ensure that `x` is not zero before attempting the division. If `x` is zero, you can return some error message or handle it in a different way according to your requirements.

Here is the updated `sample_debug` function with error handling for zero division:

```python
@llm_debugger(reflections=2, output=f'sample_debug_{timestamp}.md')
def sample_debug(x):
    if x == 0:
        # Handle the zero division error, you can raise a custom error or return a value/message
        raise ValueError("Cannot divide by zero")  # As an example, raising a ValueError
    return 10 / x  # This will not raise a ZeroDivisionError if x is not 0
```

Note that in your provided code, `{timestamp}` should be replaced or formatted to include the actual timestamp. Ensure that you have the proper import or logic to generate the timestamp string for the `output` filename.

You can also log the error, return `None`, or return a custom error code depending on how you want to handle the zero division case.

Also, note that the decorator `llm_debugger` was used here in the function, make sure that the decorator is designed to handle exceptions properly, or it might mask the intended behavior of the `sample_debug` function. If the `llm_debugger` decorator is something you've defined yourself, ensure it handles errors gracefully, possibly by including a `try...except` block within the `wrapper` function to catch the `ZeroDivisionError` or any other exceptions that may occur.
LLM Reflection 2:
Upon reviewing my previous message, I notice that I correctly identified the `ZeroDivisionError` caused by dividing by zero. However, an additional aspect that could be improved is more context regarding the `llm_debugger` decorator, which is not a standard Python feature and is likely a custom decorator implemented in your codebase. Since I don't have the implementation details of the `llm_debugger` decorator, I cannot provide specific advice on how it should handle exceptions.

Also, the use of `{timestamp}` in the decorator argument implies that some string formatting should take place before passing the argument, otherwise it could lead to a `NameError` if `timestamp` is not defined.

Here's a rectified version of the `sample_debug` function with an attempt to handle the `ZeroDivisionError` more explicitly, and a placeholder for the timestamp formatting:

```python
# Make sure you import or define `llm_debugger` properly and ensure it handles exceptions as expected.

# Assuming `timestamp` is generated elsewhere, make sure to format it properly.
from datetime import datetime
timestamp = datetime.now().strftime("%Y%m%d_%H%M%S")  # Example timestamp format

@llm_debugger(reflections=2, output=f'sample_debug_{timestamp}.md')
def sample_debug(x):
    try:
        result = 10 / x
    except ZeroDivisionError:
        # Log the error, handle it, or raise an exception with a more informative message.
        raise ValueError("Cannot divide by zero") from None
    return result

# Your code where you call `sample_debug` should be prepared to handle the `ValueError`.
```

In the code sample above, I used a `try...except` block to catch and handle the `ZeroDivisionError` by turning it into a `ValueError` with a clearer message. I also included the generation of a `timestamp` using the `datetime` module. When using the function, ensure the calling code anticipates and manages the potential `ValueError`.

Remember, if the custom `llm_debugger` decorator captures and logs exceptions, it may interfere with this exception handling. Depending on how it's implemented, you may need to adjust your strategy inside the decorator or within the function itself.
----------
